<?xml version="1.0" encoding="utf-8"?>
<!-- This URDF was automatically created by SolidWorks to URDF Exporter! Originally created by Stephen Brawner (brawner@gmail.com) 
     Commit Version: 1.6.0-4-g7f85cfe  Build Version: 1.6.7995.38578
     For more information, please see http://wiki.ros.org/sw_urdf_exporter -->
<robot
  name="Assem199">
  <link
    name="base_link">
    <inertial>
      <origin
        xyz="0.01988288121305 0.0149382486281411 0.00654462728806493"
        rpy="0 0 0" />
      <mass
        value="117.621228950402" />
      <inertia
        ixx="1.3173577642445"
        ixy="-1.67011280619683E-49"
        ixz="-2.72759128022469E-33"
        iyy="1.3173577642445"
        iyz="6.33774698995058E-17"
        izz="2.35242457900804" />
    </inertial>
    <visual>
      <origin
        xyz="0 0 0"
        rpy="0 0 0" />
      <geometry>
        <mesh
          filename="package://Assem199/meshes/base_link.STL" />
      </geometry>
      <material
        name="">
        <color
          rgba="0.529411764705882 0.549019607843137 0.549019607843137 1" />
      </material>
    </visual>
    <collision>
      <origin
        xyz="0 0 0"
        rpy="0 0 0" />
      <geometry>
        <mesh
          filename="package://Assem199/meshes/base_link.STL" />
      </geometry>
    </collision>
  </link>
  <link
    name="link1">
    <inertial>
      <origin
        xyz="0.00415497810481107 0.0360313137604443 0"
        rpy="0 0 0" />
      <mass
        value="13.9146635300317" />
      <inertia
        ixx="0.182409905304083"
        ixy="-0.00890171842578671"
        ixz="-2.42861286636753E-17"
        iyy="0.204114182321456"
        iyz="-3.46944695195361E-18"
        izz="0.177525956388747" />
    </inertial>
    <visual>
      <origin
        xyz="0 0 0"
        rpy="0 0 0" />
      <geometry>
        <mesh
          filename="package://Assem199/meshes/link1.STL" />
      </geometry>
      <material
        name="">
        <color
          rgba="0.529411764705882 0.549019607843137 0.549019607843137 1" />
      </material>
    </visual>
    <collision>
      <origin
        xyz="0 0 0"
        rpy="0 0 0" />
      <geometry>
        <mesh
          filename="package://Assem199/meshes/link1.STL" />
      </geometry>
    </collision>
  </link>
  <joint
    name="joint0"
    type="revolute">
    <origin
      xyz="0.01988288121305 0.0149382486281411 0.0765446272880649"
      rpy="1.5707963267949 0 -0.240452741469539" />
    <parent
      link="base_link" />
    <child
      link="link1" />
    <axis
      xyz="0 1 0" />
    <limit
      lower="-3.14"
      upper="0.7"
      effort="0"
      velocity="0" />
  </joint>
  <link
    name="link2">
    <inertial>
      <origin
        xyz="0.000957782668049773 -0.0423756483093979 -0.455854205736861"
        rpy="0 0 0" />
      <mass
        value="35.7606717775281" />
      <inertia
        ixx="2.15662126711767"
        ixy="0.00580032645083725"
        ixz="-0.02656498939664"
        iyy="2.19527304590314"
        iyz="0.02964240824343"
        izz="0.0766086603834945" />
    </inertial>
    <visual>
      <origin
        xyz="0 0 0"
        rpy="0 0 0" />
      <geometry>
        <mesh
          filename="package://Assem199/meshes/link2.STL" />
      </geometry>
      <material
        name="">
        <color
          rgba="0.529411764705882 0.549019607843137 0.549019607843137 1" />
      </material>
    </visual>
    <collision>
      <origin
        xyz="0 0 0"
        rpy="0 0 0" />
      <geometry>
        <mesh
          filename="package://Assem199/meshes/link2.STL" />
      </geometry>
    </collision>
  </link>
  <joint
    name="joint1"
    type="revolute">
    <origin
      xyz="0.01 0.19 0"
      rpy="0 0.86264 -1.5708" />
    <parent
      link="link1" />
    <child
      link="link2" />
    <axis
      xyz="0 1 0" />
    <limit
      lower="-1.5"
      upper="2"
      effort="0"
      velocity="0" />
  </joint>
  <link
    name="link3">
    <inertial>
      <origin
        xyz="0.000956010285404818 -0.00237526703783215 -0.455854134286277"
        rpy="0 0 0" />
      <mass
        value="35.7609521297192" />
      <inertia
        ixx="2.15662873931486"
        ixy="0.005799586567575"
        ixz="-0.0265484817320314"
        iyy="2.19527740632714"
        iyz="0.0296376151269493"
        izz="0.0766059992476047" />
    </inertial>
    <visual>
      <origin
        xyz="0 0 0"
        rpy="0 0 0" />
      <geometry>
        <mesh
          filename="package://Assem199/meshes/link3.STL" />
      </geometry>
      <material
        name="">
        <color
          rgba="0.529411764705882 0.549019607843137 0.549019607843137 1" />
      </material>
    </visual>
    <collision>
      <origin
        xyz="0 0 0"
        rpy="0 0 0" />
      <geometry>
        <mesh
          filename="package://Assem199/meshes/link3.STL" />
      </geometry>
    </collision>
  </link>
  <joint
    name="joint2"
    type="revolute">
    <origin
      xyz="0 0.00999999999999985 -0.699999999999999"
      rpy="0 -1.13764690192384 0" />
    <parent
      link="link2" />
    <child
      link="link3" />
    <axis
      xyz="0 1 0" />
    <limit
      lower="-1.5"
      upper="1.5"
      effort="0"
      velocity="0" />
  </joint>
  <link
    name="link4">
    <inertial>
      <origin
        xyz="0.00495128042923476 0.0471674039074532 -2.22044604925031E-16"
        rpy="0 0 0" />
      <mass
        value="4.02794697626435" />
      <inertia
        ixx="0.00480720378352527"
        ixy="-0.000255926816439556"
        ixz="5.42101086242752E-19"
        iyy="0.00343494333221187"
        iyz="1.23599047663348E-17"
        izz="0.00503969251705668" />
    </inertial>
    <visual>
      <origin
        xyz="0 0 0"
        rpy="0 0 0" />
      <geometry>
        <mesh
          filename="package://Assem199/meshes/link4.STL" />
      </geometry>
      <material
        name="">
        <color
          rgba="0.529411764705882 0.549019607843137 0.549019607843137 1" />
      </material>
    </visual>
    <collision>
      <origin
        xyz="0 0 0"
        rpy="0 0 0" />
      <geometry>
        <mesh
          filename="package://Assem199/meshes/link4.STL" />
      </geometry>
    </collision>
  </link>
  <joint
    name="joint3"
    type="revolute">
    <origin
      xyz="0 0 -0.700000000000006"
      rpy="0 0.515461919104493 0" />
    <parent
      link="link3" />
    <child
      link="link4" />
    <axis
      xyz="0 1 0" />
    <limit
      lower="-3.14"
      upper="3.14"
      effort="0"
      velocity="0" />
  </joint>
  <link
    name="gripper">
    <inertial>
      <origin
        xyz="-0.00970254672440024 0.161549482077784 -0.00242086494063987"
        rpy="0 0 0" />
      <mass
        value="20.8212542463535" />
      <inertia
        ixx="0.07729955880104"
        ixy="2.77555756156289E-17"
        ixz="2.84494650060196E-16"
        iyy="0.104622393225891"
        iyz="5.3776427755281E-17"
        izz="0.11043493380104" />
    </inertial>
    <visual>
      <origin
        xyz="0 0 0"
        rpy="0 0 0" />
      <geometry>
        <mesh
          filename="package://Assem199/meshes/gripper.STL" />
      </geometry>
      <material
        name="">
        <color
          rgba="0.529411764705882 0.549019607843137 0.549019607843137 1" />
      </material>
    </visual>
    <collision>
      <origin
        xyz="0 0 0"
        rpy="0 0 0" />
      <geometry>
        <mesh
          filename="package://Assem199/meshes/gripper.STL" />
      </geometry>
    </collision>
  </link>
  <joint
    name="joint4"
    type="revolute">
    <origin
      xyz="0 0.0500000000000001 0"
      rpy="0 0.244515736288296 -1.5707963267949" />
    <parent
      link="link4" />
    <child
      link="gripper" />
    <axis
      xyz="0 1 0" />
    <limit
      lower="-3.14"
      upper="3.14"
      effort="0"
      velocity="0" />
  </joint>
</robot>